<?xml version="1.0" ?>
<robot name="a" xmlns:xacro="http://www.ros.org/wiki/xacro">

<xacro:include filename="$(find a_description)/urdf/materials.xacro" />
<xacro:include filename="$(find a_description)/urdf/a.trans" />
<xacro:include filename="$(find a_description)/urdf/a.gazebo" />
<link name="base_link">
  <inertial>
    <origin xyz="-1.1580046200244058e-17 5.790023100122029e-18 0.024999999999999994" rpy="0 0 0"/>
    <mass value="3.082687791334984"/>
    <inertia ixx="0.002569" iyy="0.002569" izz="0.003853" ixy="-0.0" iyz="-0.0" ixz="-0.0"/>
  </inertial>
  <visual>
    <origin xyz="0 0 0" rpy="0 0 0"/>
    <geometry>
      <mesh filename="package://a_description/meshes/base_link.stl" scale="0.001 0.001 0.001"/>
    </geometry>
    <material name="silver"/>
  </visual>
  <collision>
    <origin xyz="0 0 0" rpy="0 0 0"/>
    <geometry>
      <mesh filename="package://a_description/meshes/base_link.stl" scale="0.001 0.001 0.001"/>
    </geometry>
  </collision>
</link>

<link name="link_1_1">
  <inertial>
    <origin xyz="0.022050626905754808 -1.0958717841084449e-17 0.04273601239650884" rpy="0 0 0"/>
    <mass value="6.514934969993694"/>
    <inertia ixx="0.008197" iyy="0.010564" izz="0.010511" ixy="0.0" iyz="0.0" ixz="-0.001515"/>
  </inertial>
  <visual>
    <origin xyz="-0.0 -0.0 -0.05" rpy="0 0 0"/>
    <geometry>
      <mesh filename="package://a_description/meshes/link_1_1.stl" scale="0.001 0.001 0.001"/>
    </geometry>
    <material name="silver"/>
  </visual>
  <collision>
    <origin xyz="-0.0 -0.0 -0.05" rpy="0 0 0"/>
    <geometry>
      <mesh filename="package://a_description/meshes/link_1_1.stl" scale="0.001 0.001 0.001"/>
    </geometry>
  </collision>
</link>

<link name="link_2_1">
  <inertial>
    <origin xyz="0.04273601239650886 -2.1917435682168898e-17 0.022050626905754767" rpy="0 0 0"/>
    <mass value="6.514934969993694"/>
    <inertia ixx="0.010511" iyy="0.010564" izz="0.008197" ixy="-0.0" iyz="-0.0" ixz="-0.001515"/>
  </inertial>
  <visual>
    <origin xyz="-0.075 0.0 -0.1" rpy="0 0 0"/>
    <geometry>
      <mesh filename="package://a_description/meshes/link_2_1.stl" scale="0.001 0.001 0.001"/>
    </geometry>
    <material name="silver"/>
  </visual>
  <collision>
    <origin xyz="-0.075 0.0 -0.1" rpy="0 0 0"/>
    <geometry>
      <mesh filename="package://a_description/meshes/link_2_1.stl" scale="0.001 0.001 0.001"/>
    </geometry>
  </collision>
</link>

<link name="link_3_1">
  <inertial>
    <origin xyz="-0.022050626905754725 -4.3834871364337795e-17 0.04273601239650898" rpy="0 0 0"/>
    <mass value="6.514934969993694"/>
    <inertia ixx="0.008197" iyy="0.010564" izz="0.010511" ixy="0.0" iyz="-0.0" ixz="0.001515"/>
  </inertial>
  <visual>
    <origin xyz="-0.125 -0.0 -0.175" rpy="0 0 0"/>
    <geometry>
      <mesh filename="package://a_description/meshes/link_3_1.stl" scale="0.001 0.001 0.001"/>
    </geometry>
    <material name="silver"/>
  </visual>
  <collision>
    <origin xyz="-0.125 -0.0 -0.175" rpy="0 0 0"/>
    <geometry>
      <mesh filename="package://a_description/meshes/link_3_1.stl" scale="0.001 0.001 0.001"/>
    </geometry>
  </collision>
</link>

<link name="link_4_1">
  <inertial>
    <origin xyz="-0.04273601239650869 4.71224867166631e-16 0.02205062690575471" rpy="0 0 0"/>
    <mass value="6.514934969993697"/>
    <inertia ixx="0.010511" iyy="0.010564" izz="0.008197" ixy="-0.0" iyz="-0.0" ixz="0.001515"/>
  </inertial>
  <visual>
    <origin xyz="-0.05 -0.0 -0.225" rpy="0 0 0"/>
    <geometry>
      <mesh filename="package://a_description/meshes/link_4_1.stl" scale="0.001 0.001 0.001"/>
    </geometry>
    <material name="silver"/>
  </visual>
  <collision>
    <origin xyz="-0.05 -0.0 -0.225" rpy="0 0 0"/>
    <geometry>
      <mesh filename="package://a_description/meshes/link_4_1.stl" scale="0.001 0.001 0.001"/>
    </geometry>
  </collision>
</link>

<link name="link_5_1">
  <inertial>
    <origin xyz="0.02205062690575503 4.931423028487994e-16 0.04273601239650865" rpy="0 0 0"/>
    <mass value="6.5149349699937025"/>
    <inertia ixx="0.008197" iyy="0.010564" izz="0.010511" ixy="-0.0" iyz="-0.0" ixz="-0.001515"/>
  </inertial>
  <visual>
    <origin xyz="-0.0 -0.0 -0.3" rpy="0 0 0"/>
    <geometry>
      <mesh filename="package://a_description/meshes/link_5_1.stl" scale="0.001 0.001 0.001"/>
    </geometry>
    <material name="silver"/>
  </visual>
  <collision>
    <origin xyz="-0.0 -0.0 -0.3" rpy="0 0 0"/>
    <geometry>
      <mesh filename="package://a_description/meshes/link_5_1.stl" scale="0.001 0.001 0.001"/>
    </geometry>
  </collision>
</link>

<link name="link_6_1">
  <inertial>
    <origin xyz="0.04447793785209257 -0.039242672944560957 -0.0003623614965618249" rpy="0 0 0"/>
    <mass value="8.570060530218305"/>
    <inertia ixx="0.019875" iyy="0.010336" izz="0.020009" ixy="0.002329" iyz="-8.9e-05" ixz="2.2e-05"/>
  </inertial>
  <visual>
    <origin xyz="-0.075 -0.0 -0.35" rpy="0 0 0"/>
    <geometry>
      <mesh filename="package://a_description/meshes/link_6_1.stl" scale="0.001 0.001 0.001"/>
    </geometry>
    <material name="silver"/>
  </visual>
  <collision>
    <origin xyz="-0.075 -0.0 -0.35" rpy="0 0 0"/>
    <geometry>
      <mesh filename="package://a_description/meshes/link_6_1.stl" scale="0.001 0.001 0.001"/>
    </geometry>
  </collision>
</link>

<joint name="Revolute 18" type="continuous">
  <origin xyz="0.0 0.0 0.05" rpy="0 0 0"/>
  <parent link="base_link"/>
  <child link="link_1_1"/>
  <axis xyz="0.0 0.0 1.0"/>
</joint>

<joint name="Revolute 19" type="continuous">
  <origin xyz="0.075 -0.0 0.05" rpy="0 0 0"/>
  <parent link="link_1_1"/>
  <child link="link_2_1"/>
  <axis xyz="1.0 0.0 0.0"/>
</joint>

<joint name="Revolute 20" type="continuous">
  <origin xyz="0.05 0.0 0.075" rpy="0 0 0"/>
  <parent link="link_2_1"/>
  <child link="link_3_1"/>
  <axis xyz="0.0 0.0 1.0"/>
</joint>

<joint name="Revolute 21" type="continuous">
  <origin xyz="-0.075 0.0 0.05" rpy="0 0 0"/>
  <parent link="link_3_1"/>
  <child link="link_4_1"/>
  <axis xyz="-1.0 0.0 0.0"/>
</joint>

<joint name="Revolute 22" type="continuous">
  <origin xyz="-0.05 0.0 0.075" rpy="0 0 0"/>
  <parent link="link_4_1"/>
  <child link="link_5_1"/>
  <axis xyz="0.0 0.0 1.0"/>
</joint>

<joint name="Revolute 23" type="continuous">
  <origin xyz="0.075 0.0 0.05" rpy="0 0 0"/>
  <parent link="link_5_1"/>
  <child link="link_6_1"/>
  <axis xyz="1.0 0.0 0.0"/>
</joint>

</robot>
